<?xml version="1.0" ?>
<!-- =================================================================================== -->
<!-- |    This document was autogenerated by xacro from za.xacro                       | -->
<!-- |    EDITING THIS FILE BY HAND IS NOT RECOMMENDED                                 | -->
<!-- =================================================================================== -->
<robot name="za">
  <!-- link list -->
  <link name="base_link">
    <visual>
      <geometry>
        <mesh filename="package://za_description/meshes/visual/base_link.dae"/>
      </geometry>
    </visual>
    <collision>
      <geometry>
        <mesh filename="package://za_description/meshes/collision/base_link_collision.stl"/>
      </geometry>
    </collision>
  </link>
  <link name="link_1">
    <visual>
      <geometry>
        <mesh filename="package://za_description/meshes/visual/link_1.dae"/>
      </geometry>
    </visual>
    <collision>
      <geometry>
        <mesh filename="package://za_description/meshes/collision/link_1_collision.stl"/>
      </geometry>
    </collision>
  </link>
  <link name="link_2">
    <visual>
      <geometry>
        <mesh filename="package://za_description/meshes/visual/link_2.dae"/>
      </geometry>
    </visual>
    <collision>
      <geometry>
        <mesh filename="package://za_description/meshes/collision/link_2_collision.stl"/>
      </geometry>
    </collision>
  </link>
  <link name="link_3">
    <visual>
      <geometry>
        <mesh filename="package://za_description/meshes/visual/link_3.dae"/>
      </geometry>
    </visual>
    <collision>
      <geometry>
        <mesh filename="package://za_description/meshes/collision/link_3_collision.stl"/>
      </geometry>
    </collision>
  </link>
  <link name="link_4">
    <visual>
      <geometry>
        <mesh filename="package://za_description/meshes/visual/link_4.dae"/>
      </geometry>
    </visual>
    <collision>
      <geometry>
        <mesh filename="package://za_description/meshes/collision/link_4_collision.stl"/>
      </geometry>
    </collision>
  </link>
  <link name="link_5">
    <visual>
      <geometry>
        <mesh filename="package://za_description/meshes/visual/link_5.dae"/>
      </geometry>
    </visual>
    <collision>
      <geometry>
        <mesh filename="package://za_description/meshes/collision/link_5_collision.stl"/>
      </geometry>
    </collision>
  </link>
  <link name="link_6">
    <visual>
      <geometry>
        <mesh filename="package://za_description/meshes/visual/link_6.dae"/>
      </geometry>
    </visual>
    <collision>
      <geometry>
        <mesh filename="package://za_description/meshes/collision/link_6_collision.stl"/>
      </geometry>
    </collision>
  </link>
  <!-- joint list -->
  <joint name="joint_1" type="revolute">
    <parent link="base_link"/>
    <child link="link_1"/>
    <origin rpy="0.0 0.0 0.0" xyz="0 0 0.45"/>
    <axis xyz="0 0 1"/>
    <limit effort="0" lower="-2.9670597283903604" upper="2.9670597283903604" velocity="2.6179938779914944"/>
  </joint>
  <joint name="joint_2" type="revolute">
    <parent link="link_1"/>
    <child link="link_2"/>
    <origin rpy="0.0 0.0 0.0" xyz="0.025 0 0.0"/>
    <axis xyz="0 1 0"/>
    <limit effort="0" lower="-1.7453292519943295" upper="2.2689280275926285" velocity="1.9634954084936207"/>
  </joint>
  <joint name="joint_3" type="revolute">
    <parent link="link_2"/>
    <child link="link_3"/>
    <origin rpy="0.0 0.0 0.0" xyz="0.0 -0.001 0.454"/>
    <axis xyz="0 1 0"/>
    <limit effort="0" lower="-2.0943951023931953" upper="1.1344640137963142" velocity="2.6179938779914944"/>
  </joint>
  <joint name="joint_4" type="revolute">
    <parent link="link_3"/>
    <child link="link_4"/>
    <origin rpy="0.0 0.0 0.0" xyz="0.0 0.0 0.035"/>
    <axis xyz="1 0 0"/>
    <limit effort="0" lower="-3.141592653589793" upper="3.141592653589793" velocity="3.569198320328404"/>
  </joint>
  <joint name="joint_5" type="revolute">
    <parent link="link_4"/>
    <child link="link_5"/>
    <origin rpy="0.0 0.0 0.0" xyz="0.4195 0.001 0.0"/>
    <axis xyz="0 1 0"/>
    <limit effort="0" lower="-2.443460952792061" upper="2.443460952792061" velocity="3.9269908169872414"/>
  </joint>
  <joint name="joint_6" type="revolute">
    <parent link="link_5"/>
    <child link="link_6"/>
    <origin rpy="0.0 0.0 0.0" xyz="0.1175 0.0 0.0"/>
    <axis xyz="1 0 0"/>
    <limit effort="0" lower="-6.283185307179586" upper="6.283185307179586" velocity="6.283185307179586"/>
  </joint>
  <!-- ROS-Industrial 'base' frame: base_link to Tormach World Coordinates transform -->
  <link name="base"/>
  <joint name="base_link-base" type="fixed">
    <origin rpy="0 0 0" xyz="0 0 0"/>
    <parent link="base_link"/>
    <child link="base"/>
  </joint>
  <!-- ROS-Industrial 'flange' frame: attachment point for EEF models -->
  <link name="flange"/>
  <joint name="joint_6-flange" type="fixed">
    <origin rpy="0 0 0" xyz="0 0 0"/>
    <parent link="link_6"/>
    <child link="flange"/>
  </joint>
  <!-- ROS-Industrial 'tool0' frame: all-zeros tool frame -->
  <link name="tool0"/>
  <joint name="link_6-tool0" type="fixed">
    <origin rpy="0 1.5707963267948966 0" xyz="0 0 0"/>
    <parent link="flange"/>
    <child link="tool0"/>
  </joint>
  <!-- 'world' frame: default pose reference frame -->
  <link name="world"/>
  <joint name="world-base_link" type="fixed">
    <origin rpy="0 0 0" xyz="0 0 0"/>
    <parent link="world"/>
    <child link="base_link"/>
  </joint>
</robot>
